[2015-12-11 13:11:41,992: WARNING/MainProcess] /u01/Djracula/.virtualenvs/bacula-glacier/lib/python2.7/site-packages/celery/apps/worker.py:161: CDeprecationWarning: 
Starting from version 3.2 Celery will refuse to accept pickle by default.

The pickle serializer is a security concern as it may give attackers
the ability to execute any command.  It's important to secure
your broker from unauthorized access when using pickle, so we think
that enabling pickle should require a deliberate action and not be
the default choice.

If you depend on pickle then you should set a setting to disable this
warning and to be sure that everything will continue working
when you upgrade to Celery 3.2::

    CELERY_ACCEPT_CONTENT = ['pickle', 'json', 'msgpack', 'yaml']

You must only enable the serializers that you will actually use.


  warnings.warn(CDeprecationWarning(W_PICKLE_DEPRECATED))
[2015-12-11 13:11:42,073: INFO/MainProcess] Connected to amqp://guest:**@127.0.0.1:5672//
[2015-12-11 13:11:42,119: INFO/MainProcess] mingle: searching for neighbors
[2015-12-11 13:11:43,160: INFO/MainProcess] mingle: sync with 1 nodes
[2015-12-11 13:11:43,160: INFO/MainProcess] mingle: sync complete
[2015-12-11 13:11:43,195: WARNING/MainProcess] w2@ckerns-rhel6.novalocal ready.
[2015-12-11 13:11:43,205: INFO/MainProcess] Received task: glacier.get_vols[d0dff179-7f2d-40cb-bd8a-43b4b6f7c501]
[2015-12-11 13:11:43,285: INFO/MainProcess] Task glacier.get_vols[d0dff179-7f2d-40cb-bd8a-43b4b6f7c501] succeeded in 0.0788333410019s: [('glacier-2_FullVol17',)]
[2015-12-11 13:11:43,314: INFO/MainProcess] Received task: glacier.upload_glacier[1c7132c6-3b52-45dd-a387-c9b1cc4c0733]
[2015-12-11 13:11:43,315: INFO/MainProcess] Received task: glacier.upload_glacier[f604ea0c-2c20-4ad7-afab-ad826a51d47e]
[2015-12-11 13:11:43,316: INFO/MainProcess] Received task: glacier.upload_glacier[97da5ba3-d60c-4f7f-a47e-459d32f15232]
[2015-12-11 13:11:43,340: INFO/Worker-1] Found credentials in shared credentials file: ~/.aws/credentials
[2015-12-11 13:11:46,405: INFO/MainProcess] sync with w3@ckerns-rhel6.novalocal
[2015-12-11 13:11:50,449: INFO/MainProcess] sync with w4@ckerns-rhel6.novalocal
[2015-12-11 14:24:08,909: INFO/Worker-1] Starting new HTTPS connection (1): glacier.us-east-1.amazonaws.com
[2015-12-11 15:32:51,755: ERROR/MainProcess] Task glacier.upload_glacier[1c7132c6-3b52-45dd-a387-c9b1cc4c0733] raised unexpected: ClientError('An error occurred (InvalidParameterValueException) when calling the UploadArchive operation: Invalid Content-Length: 95147241500',)
Traceback (most recent call last):
  File "/u01/Djracula/.virtualenvs/bacula-glacier/lib/python2.7/site-packages/celery/app/trace.py", line 240, in trace_task
    R = retval = fun(*args, **kwargs)
  File "/u01/Djracula/.virtualenvs/bacula-glacier/lib/python2.7/site-packages/celery/app/trace.py", line 438, in __protected_call__
    return self.run(*args, **kwargs)
  File "/u01/bacula-glacier/glacier.py", line 30, in upload_glacier
    upload_arc = glacier_conn.upload_archive(vaultName=vault, archiveDescription=description, body=f)
  File "/u01/Djracula/.virtualenvs/bacula-glacier/lib/python2.7/site-packages/botocore/client.py", line 310, in _api_call
    return self._make_api_call(operation_name, kwargs)
  File "/u01/Djracula/.virtualenvs/bacula-glacier/lib/python2.7/site-packages/botocore/client.py", line 396, in _make_api_call
    raise ClientError(parsed_response, operation_name)
ClientError: An error occurred (InvalidParameterValueException) when calling the UploadArchive operation: Invalid Content-Length: 95147241500
[2015-12-11 16:53:23,204: INFO/Worker-1] Starting new HTTPS connection (1): glacier.us-east-1.amazonaws.com
[2015-12-11 18:11:05,584: ERROR/MainProcess] Task glacier.upload_glacier[f604ea0c-2c20-4ad7-afab-ad826a51d47e] raised unexpected: ClientError('An error occurred (InvalidParameterValueException) when calling the UploadArchive operation: Invalid Content-Length: 95147241500',)
Traceback (most recent call last):
  File "/u01/Djracula/.virtualenvs/bacula-glacier/lib/python2.7/site-packages/celery/app/trace.py", line 240, in trace_task
    R = retval = fun(*args, **kwargs)
  File "/u01/Djracula/.virtualenvs/bacula-glacier/lib/python2.7/site-packages/celery/app/trace.py", line 438, in __protected_call__
    return self.run(*args, **kwargs)
  File "/u01/bacula-glacier/glacier.py", line 30, in upload_glacier
    upload_arc = glacier_conn.upload_archive(vaultName=vault, archiveDescription=description, body=f)
  File "/u01/Djracula/.virtualenvs/bacula-glacier/lib/python2.7/site-packages/botocore/client.py", line 310, in _api_call
    return self._make_api_call(operation_name, kwargs)
  File "/u01/Djracula/.virtualenvs/bacula-glacier/lib/python2.7/site-packages/botocore/client.py", line 396, in _make_api_call
    raise ClientError(parsed_response, operation_name)
ClientError: An error occurred (InvalidParameterValueException) when calling the UploadArchive operation: Invalid Content-Length: 95147241500
[2015-12-11 19:36:48,240: INFO/Worker-1] Starting new HTTPS connection (1): glacier.us-east-1.amazonaws.com
[2015-12-11 20:42:48,907: ERROR/MainProcess] Task glacier.upload_glacier[97da5ba3-d60c-4f7f-a47e-459d32f15232] raised unexpected: ClientError('An error occurred (InvalidParameterValueException) when calling the UploadArchive operation: Invalid Content-Length: 95147241500',)
Traceback (most recent call last):
  File "/u01/Djracula/.virtualenvs/bacula-glacier/lib/python2.7/site-packages/celery/app/trace.py", line 240, in trace_task
    R = retval = fun(*args, **kwargs)
  File "/u01/Djracula/.virtualenvs/bacula-glacier/lib/python2.7/site-packages/celery/app/trace.py", line 438, in __protected_call__
    return self.run(*args, **kwargs)
  File "/u01/bacula-glacier/glacier.py", line 30, in upload_glacier
    upload_arc = glacier_conn.upload_archive(vaultName=vault, archiveDescription=description, body=f)
  File "/u01/Djracula/.virtualenvs/bacula-glacier/lib/python2.7/site-packages/botocore/client.py", line 310, in _api_call
    return self._make_api_call(operation_name, kwargs)
  File "/u01/Djracula/.virtualenvs/bacula-glacier/lib/python2.7/site-packages/botocore/client.py", line 396, in _make_api_call
    raise ClientError(parsed_response, operation_name)
ClientError: An error occurred (InvalidParameterValueException) when calling the UploadArchive operation: Invalid Content-Length: 95147241500
